Workbook

Sheet Summary
A1: Annotation Review — Summary
A2: Paper ID | B2: Title | C2: Extracted | D2: Approved | E2: Rejected | F2: Modified | G2: Pending | H2: Sheet
A3: 1021 | B3: Oral Microbiome of Crohn's Disease Patients With and Without Oral Manifestations | C3: 14 | D3: =COUNTIF('P1021'!M3:M16,"approved") | E3: =COUNTIF('P1021'!M3:M16,"rejected") | F3: =COUNTIF('P1021'!M3:M16,"modified") | G3: =14-D3-E3-F3 | H3: → P1021
A4: 1100 | B4: Lung function and microbiota diversity in cystic fibrosis | C4: 12 | D4: =COUNTIF('P1100'!M3:M14,"approved") | E4: =COUNTIF('P1100'!M3:M14,"rejected") | F4: =COUNTIF('P1100'!M3:M14,"modified") | G4: =12-D4-E4-F4 | H4: → P1100
A5: 1117 | B5: The closed eye harbours a unique microbiome in dry eye disease | C5: 40 | D5: =COUNTIF('P1117'!M3:M42,"approved") | E5: =COUNTIF('P1117'!M3:M42,"rejected") | F5: =COUNTIF('P1117'!M3:M42,"modified") | G5: =40-D5-E5-F5 | H5: → P1117
A6: 1128 | B6: Fecal Microbiota Transplantation (FMT) From a Human at Low Risk for Alzheimer's Disease Improves Short-Term Recognition Memory and Increases Neuroinflammation in a 3xTg AD Mouse Model | C6: 12 | D6: =COUNTIF('P1128'!M3:M14,"approved") | E6: =COUNTIF('P1128'!M3:M14,"rejected") | F6: =COUNTIF('P1128'!M3:M14,"modified") | G6: =12-D6-E6-F6 | H6: → P1128
A7: 1220 | B7: Comparative analysis of the bronchoalveolar microbiome in Portuguese patients with different chronic lung disorders | C7: 7 | D7: =COUNTIF('P1220'!M3:M9,"approved") | E7: =COUNTIF('P1220'!M3:M9,"rejected") | F7: =COUNTIF('P1220'!M3:M9,"modified") | G7: =7-D7-E7-F7 | H7: → P1220
A8: 1240 | B8: Whole Genome Profiling of Lung Microbiome in Solid Organ Transplant Recipients Reveals Virus Involved Microecology May Worsen Prognosis | C8: 4 | D8: =COUNTIF('P1240'!M3:M6,"approved") | E8: =COUNTIF('P1240'!M3:M6,"rejected") | F8: =COUNTIF('P1240'!M3:M6,"modified") | G8: =4-D8-E8-F8 | H8: → P1240
A9: 134 | B9: Shotgun metagenomics reveals the gut microbial diversity and functions in Vespa mandarinia (Hymenoptera: Vespidae) at multiple life stages | C9: 0 | D9: 0 | E9: 0 | F9: 0 | G9: manual | H9: → P134
A10: 141 | B10: Reproducibility and Comparability of Fecal Microbiome Associations with Colorectal Cancer in a Cross-Sectional Study | C10: 13 | D10: =COUNTIF('P141'!M3:M15,"approved") | E10: =COUNTIF('P141'!M3:M15,"rejected") | F10: =COUNTIF('P141'!M3:M15,"modified") | G10: =13-D10-E10-F10 | H10: → P141
A11: 1421 | B11: Periodontitis-related salivary microbiota aggravates Alzheimer's disease via gut-brain axis crosstalk | C11: 15 | D11: =COUNTIF('P1421'!M3:M17,"approved") | E11: =COUNTIF('P1421'!M3:M17,"rejected") | F11: =COUNTIF('P1421'!M3:M17,"modified") | G11: =15-D11-E11-F11 | H11: → P1421
A12: 1594 | B12: The altered sputum microbiome profile in patients with moderate and severe COPD exacerbations, compared to the healthy group in the Indian population | C12: 19 | D12: =COUNTIF('P1594'!M3:M21,"approved") | E12: =COUNTIF('P1594'!M3:M21,"rejected") | F12: =COUNTIF('P1594'!M3:M21,"modified") | G12: =19-D12-E12-F12 | H12: → P1594
A13: 1595 | B13: Variations of the lung microbiome and immune response in mechanically ventilated surgical patients | C13: 15 | D13: =COUNTIF('P1595'!M3:M17,"approved") | E13: =COUNTIF('P1595'!M3:M17,"rejected") | F13: =COUNTIF('P1595'!M3:M17,"modified") | G13: =15-D13-E13-F13 | H13: → P1595
A14: 1638 | B14: Fecal microbiota transplant overcomes resistance to anti-PD-1 therapy in melanoma patients | C14: 19 | D14: =COUNTIF('P1638'!M3:M21,"approved") | E14: =COUNTIF('P1638'!M3:M21,"rejected") | F14: =COUNTIF('P1638'!M3:M21,"modified") | G14: =19-D14-E14-F14 | H14: → P1638
A15: 166 | B15: Salivary microbiome profiles of oral cancer patients analyzed before and after treatment | C15: 39 | D15: =COUNTIF('P166'!M3:M41,"approved") | E15: =COUNTIF('P166'!M3:M41,"rejected") | F15: =COUNTIF('P166'!M3:M41,"modified") | G15: =39-D15-E15-F15 | H15: → P166
A16: 1690 | B16: Disrupted gut microbiota promotes the progression of chronic kidney disease in 5/6 nephrectomy mice by Bacillus pumilus gavage | C16: 7 | D16: =COUNTIF('P1690'!M3:M9,"approved") | E16: =COUNTIF('P1690'!M3:M9,"rejected") | F16: =COUNTIF('P1690'!M3:M9,"modified") | G16: =7-D16-E16-F16 | H16: → P1690
A17: 1874 | B17: Characteristics of tongue coating microbiota in diabetic and non-diabetic kidney patients receiving hemodialysis | C17: 24 | D17: =COUNTIF('P1874'!M3:M26,"approved") | E17: =COUNTIF('P1874'!M3:M26,"rejected") | F17: =COUNTIF('P1874'!M3:M26,"modified") | G17: =24-D17-E17-F17 | H17: → P1874
A18: 193 | B18: Characterization of the nasal and oral microbiota of detection dogs | C18: 0 | D18: 0 | E18: 0 | F18: 0 | G18: manual | H18: → P193
A19: 1983 | B19: Brief antibiotic use drives human gut bacteria towards low-cost resistance | C19: 3 | D19: =COUNTIF('P1983'!M3:M5,"approved") | E19: =COUNTIF('P1983'!M3:M5,"rejected") | F19: =COUNTIF('P1983'!M3:M5,"modified") | G19: =3-D19-E19-F19 | H19: → P1983
A20: 199 | B20: Distinct nasal airway bacterial microbiotas differentially relate to exacerbation in pediatric patients with asthma | C20: 19 | D20: =COUNTIF('P199'!M3:M21,"approved") | E20: =COUNTIF('P199'!M3:M21,"rejected") | F20: =COUNTIF('P199'!M3:M21,"modified") | G20: =19-D20-E20-F20 | H20: → P199
A21: 2007 | B21: A population-scale analysis of 36 gut microbiome studies reveals universal species signatures for common diseases | C21: 66 | D21: =COUNTIF('P2007'!M3:M68,"approved") | E21: =COUNTIF('P2007'!M3:M68,"rejected") | F21: =COUNTIF('P2007'!M3:M68,"modified") | G21: =66-D21-E21-F21 | H21: → P2007
A22: 206 | B22: Gut-associated microbes are present and active in the pig nasal cavity | C22: 1 | D22: =COUNTIF('P206'!M3:M3,"approved") | E22: =COUNTIF('P206'!M3:M3,"rejected") | F22: =COUNTIF('P206'!M3:M3,"modified") | G22: =1-D22-E22-F22 | H22: → P206
A23: 208 | B23: Determination of nasal and oropharyngeal microbiomes in a multicenter population-based study – findings from Pretest 1 of the German National Cohort | C23: 0 | D23: 0 | E23: 0 | F23: 0 | G23: manual | H23: → P208
A24: 435 | B24: Dynamic alterations in the lung microbiota in a rat model of lipopolysaccharide-induced acute lung injury | C24: 20 | D24: =COUNTIF('P435'!M3:M22,"approved") | E24: =COUNTIF('P435'!M3:M22,"rejected") | F24: =COUNTIF('P435'!M3:M22,"modified") | G24: =20-D24-E24-F24 | H24: → P435
A25: 451 | B25: Characterization of the upper and lower respiratory tract microbiota in Piedmontese calves | C25: 14 | D25: =COUNTIF('P451'!M3:M16,"approved") | E25: =COUNTIF('P451'!M3:M16,"rejected") | F25: =COUNTIF('P451'!M3:M16,"modified") | G25: =14-D25-E25-F25 | H25: → P451
A26: 461 | B26: Impact of Fecal Microbiota Transplantation on Gut Bacterial Bile Acid Metabolism in Humans | C26: 15 | D26: =COUNTIF('P461'!M3:M17,"approved") | E26: =COUNTIF('P461'!M3:M17,"rejected") | F26: =COUNTIF('P461'!M3:M17,"modified") | G26: =15-D26-E26-F26 | H26: → P461
A27: 626 | B27: Whole genome sequencing revealed microbiome in lung adenocarcinomas presented as ground-glass nodules | C27: 5 | D27: =COUNTIF('P626'!M3:M7,"approved") | E27: =COUNTIF('P626'!M3:M7,"rejected") | F27: =COUNTIF('P626'!M3:M7,"modified") | G27: =5-D27-E27-F27 | H27: → P626
A28: 756 | B28: The Effects of Electronic Cigarettes on Oral Microbiome and Metabolome in 3D Tissue-Engineered Models | C28: 17 | D28: =COUNTIF('P756'!M3:M19,"approved") | E28: =COUNTIF('P756'!M3:M19,"rejected") | F28: =COUNTIF('P756'!M3:M19,"modified") | G28: =17-D28-E28-F28 | H28: → P756
A29: 856 | B29: Gut microbiome and schizophrenia: insights from two-sample Mendelian randomization | C29: 26 | D29: =COUNTIF('P856'!M3:M28,"approved") | E29: =COUNTIF('P856'!M3:M28,"rejected") | F29: =COUNTIF('P856'!M3:M28,"modified") | G29: =26-D29-E29-F29 | H29: → P856
A30: 943 | B30: Oral Microbiome in Nonsmoker Patients with Oral Cavity Squamous Cell Carcinoma, Defined by Metagenomic Shotgun Sequencing | C30: 30 | D30: =COUNTIF('P943'!M3:M32,"approved") | E30: =COUNTIF('P943'!M3:M32,"rejected") | F30: =COUNTIF('P943'!M3:M32,"modified") | G30: =30-D30-E30-F30 | H30: → P943
A31: 961 | B31: Microbiota in Gut, Oral Cavity, and Mitral Valves Are Associated With Rheumatic Heart Disease | C31: 46 | D31: =COUNTIF('P961'!M3:M48,"approved") | E31: =COUNTIF('P961'!M3:M48,"rejected") | F31: =COUNTIF('P961'!M3:M48,"modified") | G31: =46-D31-E31-F31 | H31: → P961
A32: 988 | B32: THE ROLE OF GUT MICROBIOTA IN FETAL METHYLMERCURY EXPOSURE: INSIGHTS FROM A PILOT STUDY | C32: 8 | D32: =COUNTIF('P988'!M3:M10,"approved") | E32: =COUNTIF('P988'!M3:M10,"rejected") | F32: =COUNTIF('P988'!M3:M10,"modified") | G32: =8-D32-E32-F32 | H32: → P988
A33: TOTAL | C33: =SUM(C3:C32) | D33: =SUM(D3:D32) | E33: =SUM(E3:E32) | F33: =SUM(F3:F32) | G33: =SUM(G3:G32)

Sheet P1021
A1: Paper 1021 — Oral Microbiome of Crohn's Disease Patients With and Without Oral Manifestations
A2: TAXON NAME | B2: DOMAIN | C2: TAXONOMIC LEVEL | D2: PRIMARY DISEASE | E2: DIRECTION | F2: CHANGE CONTEXT | G2: SAMPLE SITE | H2: P VALUE | I2: CONFIDENCE | J2: AGREEMENT | K2: QUEEN DECISION | L2: VERBATIM EVIDENCE | M2: STATUS | N2: CORRECTION | O2: SAM NOTES
A3: Actinomycetota | B3: bacteria | C3: phylum | D3: Crohn's disease | E3: increased | F3: disease_vs_control | G3: oral | I3: medium | J3: verified | K3: keep | L3: Patients with CD were found to have increased saliva microbial species of the phyla Actinomycetota [Actinobacteria] and Pseudomonadota [Proteobacteria], but no significant differences in the total abundance of microbial species of the phyla Bacillota [Firmicutes] and Bacteroidota [Bacteroidetes]
A4: Pseudomonadota | B4: bacteria | C4: phylum | D4: Crohn's disease | E4: increased | F4: disease_vs_control | G4: oral | I4: medium | J4: verified | K4: keep | L4: Patients with CD were found to have increased saliva microbial species of the phyla Actinomycetota [Actinobacteria] and Pseudomonadota [Proteobacteria], but no significant differences in the total abundance of microbial species of the phyla Bacillota [Firmicutes] and Bacteroidota [Bacteroidetes]
A5: Bacillota | B5: bacteria | C5: phylum | D5: Crohn's disease | E5: unchanged | F5: disease_vs_control | G5: oral | I5: medium | J5: verified | K5: keep | L5: Patients with CD were found to have increased saliva microbial species of the phyla Actinomycetota [Actinobacteria] and Pseudomonadota [Proteobacteria], but no significant differences in the total abundance of microbial species of the phyla Bacillota [Firmicutes] and Bacteroidota [Bacteroidetes], with a corresponding borderline increase in the ratio of Bacillota [Firmicutes] to Bacteroidota [Bacteroidetes], though not statistically significant [p = 0. 44]
A6: Bacteroidota | B6: bacteria | C6: phylum | D6: Crohn's disease | E6: unchanged | F6: disease_vs_control | G6: oral | I6: medium | J6: verified | K6: keep | L6: Patients with CD were found to have increased saliva microbial species of the phyla Actinomycetota [Actinobacteria] and Pseudomonadota [Proteobacteria], but no significant differences in the total abundance of microbial species of the phyla Bacillota [Firmicutes] and Bacteroidota [Bacteroidetes]
A7: Roseburia intestinalis | B7: bacteria | C7: species | D7: Crohn's disease | E7: unclear | F7: disease_vs_control | G7: oral | I7: medium | J7: verified | K7: keep_flagged | L7: Four microbial species each were found associated with either cobblestoning [Roseburia intestinalis, Bacteroides vulgatus, Clostridium asparagiforme and Bacteriodes dorei] or oral ulcers [Turicimonas muris, Anaerostipes hadrus, Clostridium bolteae and Roseburia inulinivorans].
A8: Bacteroides vulgatus | B8: bacteria | C8: species | D8: Crohn's disease | E8: unclear | F8: disease_vs_control | G8: oral | I8: medium | J8: verified | K8: keep_flagged | L8: Four microbial species each were found associated with either cobblestoning [Roseburia intestinalis, Bacteroides vulgatus, Clostridium asparagiforme and Bacteriodes dorei] or oral ulcers [Turicimonas muris, Anaerostipes hadrus, Clostridium bolteae and Roseburia inulinivorans].
A9: Clostridium asparagiforme | B9: bacteria | C9: species | D9: Crohn's disease | E9: unclear | F9: disease_vs_control | G9: oral | I9: medium | J9: verified | K9: keep_flagged | L9: Four microbial species each were found associated with either cobblestoning [Roseburia intestinalis, Bacteroides vulgatus, Clostridium asparagiforme and Bacteriodes dorei] or oral ulcers [Turicimonas muris, Anaerostipes hadrus, Clostridium bolteae and Roseburia inulinivorans].
A10: Bacteroides dorei | B10: bacteria | C10: species | D10: Crohn's disease | E10: unclear | F10: disease_vs_control | G10: oral | I10: medium | J10: verified | K10: keep_flagged | L10: Four microbial species each were found associated with either cobblestoning [Roseburia intestinalis, Bacteroides vulgatus, Clostridium asparagiforme and Bacteriodes dorei] or oral ulcers [Turicimonas muris, Anaerostipes hadrus, Clostridium bolteae and Roseburia inulinivorans].
A11: Turicimonas muris | B11: bacteria | C11: species | D11: Crohn's disease | E11: unclear | F11: disease_vs_control | G11: oral | I11: medium | J11: verified | K11: keep_flagged | L11: Four microbial species each were found associated with either cobblestoning [Roseburia intestinalis, Bacteroides vulgatus, Clostridium asparagiforme and Bacteriodes dorei] or oral ulcers [Turicimonas muris, Anaerostipes hadrus, Clostridium bolteae and Roseburia inulinivorans].
A12: Anaerostipes hadrus | B12: bacteria | C12: species | D12: Crohn's disease | E12: increased | F12: disease_vs_control | G12: oral | I12: high | J12: verified | K12: keep | L12: This was further substantiated by the finding of an increased abundance of A. hadrus in subjects with oral ulcers, a major butyrate producer usually found in the gut
A13: Clostridium bolteae | B13: bacteria | C13: species | D13: Crohn's disease | E13: unclear | F13: disease_vs_control | G13: oral | I13: medium | J13: verified | K13: keep_flagged | L13: Four microbial species each were found associated with either cobblestoning [Roseburia intestinalis, Bacteroides vulgatus, Clostridium asparagiforme and Bacteriodes dorei] or oral ulcers [Turicimonas muris, Anaerostipes hadrus, Clostridium bolteae and Roseburia inulinivorans].
A14: Roseburia inulinivorans | B14: bacteria | C14: species | D14: Crohn's disease | E14: unclear | F14: disease_vs_control | G14: oral | I14: medium | J14: verified | K14: keep_flagged | L14: Four microbial species each were found associated with either cobblestoning [Roseburia intestinalis, Bacteroides vulgatus, Clostridium asparagiforme and Bacteriodes dorei] or oral ulcers [Turicimonas muris, Anaerostipes hadrus, Clostridium bolteae and Roseburia inulinivorans].
... A16: Faecalibacterium prausnitzii | B16: bacteria | C16: species | D16: Crohn's disease | E16: decreased | F16: disease_vs_control | G16: oral | I16: low | J16: verified | K16: keep_flagged | L16: Differentially abundant oral microbes in CD were predominantly the same stool species associated with IBD [i. e. increased abundances of Ruminococcus gnavus, decreased abundance of Faecalibacterium prausnitzii]

Sheet P1100
A1: Paper 1100 — Lung function and microbiota diversity in cystic fibrosis
A2: TAXON NAME | B2: DOMAIN | C2: TAXONOMIC LEVEL | D2: PRIMARY DISEASE | E2: DIRECTION | F2: CHANGE CONTEXT | G2: SAMPLE SITE | H2: P VALUE | I2: CONFIDENCE | J2: AGREEMENT | K2: QUEEN DECISION | L2: VERBATIM EVIDENCE | M2: STATUS | N2: CORRECTION | O2: SAM NOTES
A3: Pseudomonas aeruginosa | B3: bacteria | C3: species | D3: cystic fibrosis | E3: increased | F3: disease_vs_control | G3: lung | I3: high | J3: verified | K3: keep | L3: A clear pattern emerged of increasing dominance by recognised pathogens, which was mainly driven by the OTU identified as P. aeruginosa, as lung function decreased (Fig. 4a).
A4: Staphylococcus aureus | B4: bacteria | C4: species | D4: cystic fibrosis | E4: increased | F4: disease_vs_control | G4: lung | I4: medium | J4: verified | K4: keep | L4: From the top six OTUs that contributed most to the dissimilarity, these included five identified as recognised CF respiratory pathogens, including P. aeruginosa, S. aureus, B. cepacia complex, S. maltophilia (all core taxa in all categories) and H. influenzae (satellite taxon in all categories).
A5: Burkholderia cepacia complex | B5: bacteria | C5: species | D5: cystic fibrosis | E5: increased | F5: disease_vs_control | G5: lung | I5: medium | J5: verified | K5: keep | L5: From the top six OTUs that contributed most to the dissimilarity, these included five identified as recognised CF respiratory pathogens, including P. aeruginosa, S. aureus, B. cepacia complex, S. maltophilia (all core taxa in all categories) and H. influenzae.
A6: Stenotrophomonas maltophilia | B6: bacteria | C6: species | D6: cystic fibrosis | E6: increased | F6: disease_vs_control | G6: lung | I6: medium | J6: verified | K6: keep | L6: From the top six OTUs that contributed most to the dissimilarity, these included five identified as recognised CF respiratory pathogens, including P. aeruginosa, S. aureus, B. cepacia complex, S. maltophilia (all core taxa in all categories) and H. influenzae.
A7: Haemophilus influenzae | B7: bacteria | C7: species | D7: cystic fibrosis | E7: increased | F7: disease_vs_control | G7: lung | I7: medium | J7: verified | K7: keep | L7: From the top six OTUs that contributed most to the dissimilarity, these included five identified as recognised CF respiratory pathogens, including P. aeruginosa, S. aureus, B. cepacia complex, S. maltophilia (all core taxa in all categories) and H. influenzae (satellite taxon in all categories).
A8: Achromobacter xylosoxidans | B8: bacteria | C8: species | D8: cystic fibrosis | E8: unclear | F8: disease_vs_control | G8: lung | I8: low | J8: verified | K8: keep_flagged | L8: SIMPER analysis revealed that all recognised pathogen OTUs, with the exception of A. xylosoxidans, contributed substantially to the dissimilarity between lung disease categories (Table 2). In addition, the lung microbiota of individual patients became increasingly dominated by recognised pathogen OTUs, and especially by the P. aeruginosa OTU, in concert with decreasing lung function (Fig. 4). Again, A. xylosoxidans stood as an exception to this rule. Our findings, therefore, bring into question the perceived importance of this species in CF.
A9: Prevotella melaninogenica | B9: bacteria | C9: species | D9: cystic fibrosis | E9: decreased | F9: disease_vs_control | G9: lung | I9: high | J9: verified | K9: keep | L9: Conversely, better lung function associated with increasing dominance by other bacterial taxa, especially the putative P. melaninogenica OTU (Fig. 4b). Additionally, the second top taxon was an OTU identified as belonging to the Prevotella genus, putatively labelled as P. melaninogenica.
A10: Prevotella | B10: bacteria | C10: genus | D10: cystic fibrosis | E10: decreased | F10: disease_vs_control | G10: lung | I10: high | J10: verified | K10: keep | L10: Conversely, other bacteria, but especially OTUs identified as belonging to genera comprised of obligate anaerobes, were observed to increasingly dominate microbiota of patients with better lung function (Fig. 4). Taxa belonging to the genera of Prevotella, Porphyromonas, and Veillonella, as observed here, have been previously associated with better clinical outcomes when they dominate lung microbiota.
A11: Porphyromonas | B11: bacteria | C11: genus | D11: cystic fibrosis | E11: decreased | F11: disease_vs_control | G11: lung | I11: medium | J11: verified | K11: keep | L11: Taxa belonging to the genera of Prevotella, Porphyromonas, and Veillonella, as observed here, have been previously associated with better clinical outcomes when they dominate lung microbiota.
A12: Veillonella | B12: bacteria | C12: genus | D12: cystic fibrosis | E12: decreased | F12: disease_vs_control | G12: lung | I12: medium | J12: verified | K12: keep | L12: Taxa belonging to the genera of Prevotella, Porphyromonas, and Veillonella, as observed here, have been previously associated with better clinical outcomes when they dominate lung microbiota.
A13: Rothia | B13: bacteria | C13: genus | D13: cystic fibrosis | E13: decreased | F13: disease_vs_control | G13: lung | I13: low | J13: verified | K13: keep_flagged | L13: The remaining taxa within the SIMPER table predominantly comprised OTUs from the Streptococcus genus or OTUs from genera consisted of strict anaerobic species, including Prevotella, Porphyromonas, Rothia and Veillonella (Table 2).
A14: Streptococcus | B14: bacteria | C14: genus | D14: cystic fibrosis | E14: unclear | F14: disease_vs_control | G14: lung | I14: low | J14: verified | K14: keep_flagged | L14: The remaining taxa within the SIMPER table predominantly comprised OTUs from the Streptococcus genus or OTUs from genera consisted of strict anaerobic species, including Prevotella, Porphyromonas, Rothia and Veillonella (Table 2).

Sheet P1117
A1: Paper 1117 — The closed eye harbours a unique microbiome in dry eye disease
A2: TAXON NAME | B2: DOMAIN | C2: TAXONOMIC LEVEL | D2: PRIMARY DISEASE | E2: DIRECTION | F2: CHANGE CONTEXT | G2: SAMPLE SITE | H2: P VALUE | I2: CONFIDENCE | J2: AGREEMENT | K2: QUEEN DECISION | L2: VERBATIM EVIDENCE | M2: STATUS | N2: CORRECTION | O2: SAM NOTES
A3: Pseudomonas | B3: bacteria | C3: genus | D3: dry eye disease | E3: decreased | F3: disease_vs_control | G3: other | H3: < 2e-22 | I3: high | J3: verified | K3: keep | L3: A more rigorous normalization performed on our dataset confirmed the reduction in Pseudomonas spp. but not in Staphylococcus spp.
A4: Methylobacteriaceae | B4: bacteria | C4: family | D4: dry eye disease | E4: increased | F4: disease_vs_control | G4: other | H4: < 2e-22 | I4: high | J4: verified | K4: keep | L4: univariate analysis of the relative abundance of bacterial genera showed individuals with dry eye disease have differences in the relative abundance of 113 genera, with the most significant differences in OPB56, Methylobacteriaceae, Bacteroidetes, Pseudomonas, and Meiothermus (all with FDR-adjusted P < 2 × 10−22)
A5: Meiothermus | B5: bacteria | C5: genus | D5: dry eye disease | E5: unclear | F5: disease_vs_control | G5: other | H5: < 2e-22 | I5: high | J5: verified | K5: keep | L5: univariate analysis of the relative abundance of bacterial genera showed individuals with dry eye disease have differences in the relative abundance of 113 genera, with the most significant differences in OPB56, Methylobacteriaceae, Bacteroidetes, Pseudomonas, and Meiothermus (all with FDR-adjusted P < 2 × 10−22)
A6: OPB56 | B6: bacteria | C6: order | D6: dry eye disease | E6: decreased | F6: disease_vs_control | G6: other | H6: < 2e-22 | I6: high | J6: verified | K6: keep_flagged | L6: Discriminant analysis of principal components at the order level revealed the abundances of orders OPB56 and Rhizobiales are important to discriminate the normal eye while the orders Halanaerobiales, Erysipelotrichales and Anaeroplasmatales are important to discriminate dry eye
A7: Verrucomicrobia | B7: bacteria | C7: phylum | D7: dry eye disease | E7: unclear | F7: disease_vs_control | G7: other | H7: 4.6e-11 | I7: high | J7: verified | K7: keep | L7: At the phylum level, Firmicutes and Bacteroidetes remained unchanged, while Verrucomicrobia (FDR P = 4.6 × 10−11) and Proteobacteria (FDR P = 6.0 × 10−10) showed the most significant differences.
A8: Proteobacteria | B8: bacteria | C8: phylum | D8: dry eye disease | E8: unclear | F8: disease_vs_control | G8: other | H8: 6.0e-10 | I8: high | J8: verified | K8: keep | L8: At the phylum level, Firmicutes and Bacteroidetes remained unchanged, while Verrucomicrobia (FDR P = 4.6 × 10−11) and Proteobacteria (FDR P = 6.0 × 10−10) showed the most significant differences.
A9: Firmicutes | B9: bacteria | C9: phylum | D9: dry eye disease | E9: unchanged | F9: disease_vs_control | G9: other | I9: high | J9: verified | K9: keep | L9: At the phylum level, Firmicutes and Bacteroidetes remained unchanged, while Verrucomicrobia (FDR P = 4.6 × 10−11) and Proteobacteria (FDR P = 6.0 × 10−10) showed the most significant differences.
A10: Bacteroidetes | B10: bacteria | C10: phylum | D10: dry eye disease | E10: unchanged | F10: disease_vs_control | G10: other | I10: high | J10: verified | K10: keep | L10: At the phylum level, Firmicutes and Bacteroidetes remained unchanged, while Verrucomicrobia (FDR P = 4.6 × 10−11) and Proteobacteria (FDR P = 6.0 × 10−10) showed the most significant differences.
A11: Bradyrhizobium | B11: bacteria | C11: genus | D11: dry eye disease | E11: unclear | F11: disease_vs_control | G11: other | H11: < 1.1e-11 | I11: high | J11: verified | K11: keep | L11: Univariate analysis using negative binomial regression identified Methylobacteriaceae, Pseudomonas, Bradyrhizobium and Allobaculum as the five most differently abundant genera (all with FDR-adjusted P < 1.1 × 10−11, Supplemental Fig. S5a and Supplemental Table 4).
A12: Allobaculum | B12: bacteria | C12: genus | D12: dry eye disease | E12: unclear | F12: disease_vs_control | G12: other | H12: < 1.1e-11 | I12: high | J12: verified | K12: keep | L12: Univariate analysis using negative binomial regression identified Methylobacteriaceae, Pseudomonas, Bradyrhizobium and Allobaculum as the five most differently abundant genera (all with FDR-adjusted P < 1.1 × 10−11, Supplemental Fig. S5a and Supplemental Table 4).
A13: Halanaerobiales | B13: bacteria | C13: order | D13: dry eye disease | E13: increased | F13: disease_vs_control | G13: other | I13: medium | J13: verified | K13: keep | L13: Discriminant analysis of principal components at the order level revealed the abundances of orders OPB56 and Rhizobiales are important to discriminate the normal eye while the orders Halanaerobiales, Erysipelotrichales and Anaeroplasmatales are important to discriminate dry eye
A14: Erysipelotrichales | B14: bacteria | C14: order | D14: dry eye disease | E14: increased | F14: disease_vs_control | G14: other | I14: medium | J14: verified | K14: keep | L14: Discriminant analysis of principal components at the order level revealed the abundances of orders OPB56 and Rhizobiales are important to discriminate the normal eye while the orders Halanaerobiales, Erysipelotrichales and Anaeroplasmatales are important to discriminate dry eye
A15: Anaeroplasmatales | B15: bacteria | C15: order | D15: dry eye disease | E15: increased | F15: disease_vs_control | G15: other | I15: medium | J15: verified | K15: keep | L15: Discriminant analysis of principal components at the order level revealed the abundances of orders OPB56 and Rhizobiales are important to discriminate the normal eye while the orders Halanaerobiales, Erysipelotrichales and Anaeroplasmatales are important to discriminate dry eye
A16: Rhizobiales | B16: bacteria | C16: order | D16: dry eye disease | E16: decreased | F16: disease_vs_control | G16: other | I16: medium | J16: verified | K16: keep | L16: Discriminant analysis of principal components at the order level revealed the abundances of orders OPB56 and Rhizobiales are important to discriminate the normal eye while the orders Halanaerobiales, Erysipelotrichales and Anaeroplasmatales are important to discriminate dry eye
A17: Helicobacter | B17: bacteria | C17: genus | D17: dry eye disease | E17: increased | F17: disease_vs_control | G17: other | I17: medium | J17: verified | K17: keep | L17: We identified 5 genera that reliably identified individuals with dry eye (Pseudomonas, Methylobacteriaceae, Helicobacter, Acetobacter and Stenotrophomonas) with 3 genera that reliably identified normal patients (Leuconostocaceae, Streptococcus and Calothrix)
A18: Acetobacter | B18: bacteria | C18: genus | D18: dry eye disease | E18: increased | F18: disease_vs_control | G18: other | I18: medium | J18: verified | K18: keep | L18: We identified 5 genera that reliably identified individuals with dry eye (Pseudomonas, Methylobacteriaceae, Helicobacter, Acetobacter and Stenotrophomonas) with 3 genera that reliably identified normal patients (Leuconostocaceae, Streptococcus and Calothrix)
A19: Stenotrophomonas | B19: bacteria | C19: genus | D19: dry eye disease | E19: increased | F19: disease_vs_control | G19: other | I19: medium | J19: verified | K19: keep | L19: We identified 5 genera that reliably identified individuals with dry eye (Pseudomonas, Methylobacteriaceae, Helicobacter, Acetobacter and Stenotrophomonas) with 3 genera that reliably identified normal patients (Leuconostocaceae, Streptococcus and Calothrix)
A20: Leuconostocaceae | B20: bacteria | C20: family | D20: dry eye disease | E20: decreased | F20: disease_vs_control | G20: other | I20: medium | J20: verified | K20: keep | L20: We identified 5 genera that reliably identified individuals with dry eye (Pseudomonas, Methylobacteriaceae, Helicobacter, Acetobacter and Stenotrophomonas) with 3 genera that reliably identified normal patients (Leuconostocaceae, Streptococcus and Calothrix)
A21: Streptococcus | B21: bacteria | C21: genus | D21: dry eye disease | E21: decreased | F21: disease_vs_control | G21: other | H21: < 0.01 | I21: high | J21: verified | K21: keep | L21: Univariate analysis detected the most significant differences in the abundance of MLE112, Lactobacillaceae, Streptococcus, Sphingobium, Caldicoprobacter and Anaerococcus (ANOVA, P < 0.01, Fig. 3c)
A22: Calothrix | B22: bacteria | C22: genus | D22: dry eye disease | E22: decreased | F22: disease_vs_control | G22: other | I22: low | J22: verified | K22: keep_flagged | L22: We identified 5 genera that reliably identified individuals with dry eye (Pseudomonas, Methylobacteriaceae, Helicobacter, Acetobacter and Stenotrophomonas) with 3 genera that reliably identified normal patients (Leuconostocaceae, Streptococcus and Calothrix)
A23: Methylobacterium | B23: bacteria | C23: genus | D23: dry eye disease | E23: increased | F23: disease_vs_control | G23: other | I23: medium | J23: verified | K23: keep | L23: variable importance analysis identified the prevalence of the genera Methylobacterium, Megasphaera, Parabacteroides, S247, Bifidobacterium, Streptococcus, Desulfovibrio, Acetobacter, Dialister and Bacillus as particularly useful to identify samples from individuals with dry eye (Importance > 20)
A24: Megasphaera | B24: bacteria | C24: genus | D24: dry eye disease | E24: unclear | F24: disease_vs_control | G24: other | I24: low | J24: verified | K24: keep | L24: variable importance analysis identified the prevalence of the genera Methylobacterium, Megasphaera, Parabacteroides, S247, Bifidobacterium, Streptococcus, Desulfovibrio, Acetobacter, Dialister and Bacillus as particularly useful to identify samples from individuals with dry eye (Importance > 20)
A25: Parabacteroides | B25: bacteria | C25: genus | D25: dry eye disease | E25: unclear | F25: disease_vs_control | G25: other | I25: low | J25: verified | K25: keep | L25: variable importance analysis identified the prevalence of the genera Methylobacterium, Megasphaera, Parabacteroides, S247, Bifidobacterium, Streptococcus, Desulfovibrio, Acetobacter, Dialister and Bacillus as particularly useful to identify samples from individuals with dry eye (Importance > 20)
A26: Bifidobacterium | B26: bacteria | C26: genus | D26: dry eye disease | E26: unclear | F26: disease_vs_control | G26: other | I26: low | J26: verified | K26: keep | L26: variable importance analysis identified the prevalence of the genera Methylobacterium, Megasphaera, Parabacteroides, S247, Bifidobacterium, Streptococcus, Desulfovibrio, Acetobacter, Dialister and Bacillus as particularly useful to identify samples from individuals with dry eye (Importance > 20)
A27: Desulfovibrio | B27: bacteria | C27: genus | D27: dry eye disease | E27: unclear | F27: disease_vs_control | G27: other | I27: low | J27: verified | K27: keep | L27: variable importance analysis identified the prevalence of the genera Methylobacterium, Megasphaera, Parabacteroides, S247, Bifidobacterium, Streptococcus, Desulfovibrio, Acetobacter, Dialister and Bacillus as particularly useful to identify samples from individuals with dry eye (Importance > 20)
A28: Dialister | B28: bacteria | C28: genus | D28: dry eye disease | E28: unclear | F28: disease_vs_control | G28: other | I28: low | J28: verified | K28: keep | L28: variable importance analysis identified the prevalence of the genera Methylobacterium, Megasphaera, Parabacteroides, S247, Bifidobacterium, Streptococcus, Desulfovibrio, Acetobacter, Dialister and Bacillus as particularly useful to identify samples from individuals with dry eye (Importance > 20)
A29: Bacillus | B29: bacteria | C29: genus | D29: dry eye disease | E29: unclear | F29: disease_vs_control | G29: other | I29: low | J29: verified | K29: keep | L29: variable importance analysis identified the prevalence of the genera Methylobacterium, Megasphaera, Parabacteroides, S247, Bifidobacterium, Streptococcus, Desulfovibrio, Acetobacter, Dialister and Bacillus as particularly useful to identify samples from individuals with dry eye (Importance > 20)
A30: Lactobacillaceae | B30: bacteria | C30: family | D30: dry eye disease | E30: unclear | F30: disease_vs_control | G30: other | H30: < 0.01 | I30: medium | J30: verified | K30: keep | L30: Univariate analysis detected the most significant differences in the abundance of MLE112, Lactobacillaceae, Streptococcus, Sphingobium, Caldicoprobacter and Anaerococcus (ANOVA, P < 0.01, Fig. 3c)
A31: Sphingobium | B31: bacteria | C31: genus | D31: dry eye disease | E31: unclear | F31: disease_vs_control | G31: other | H31: < 0.01 | I31: medium | J31: verified | K31: keep | L31: Univariate analysis detected the most significant differences in the abundance of MLE112, Lactobacillaceae, Streptococcus, Sphingobium, Caldicoprobacter and Anaerococcus (ANOVA, P < 0.01, Fig. 3c)
A32: Caldicoprobacter | B32: bacteria | C32: genus | D32: dry eye disease | E32: unclear | F32: disease_vs_control | G32: other | H32: < 0.01 | I32: medium | J32: verified | K32: keep | L32: Univariate analysis detected the most significant differences in the abundance of MLE112, Lactobacillaceae, Streptococcus, Sphingobium, Caldicoprobacter and Anaerococcus (ANOVA, P < 0.01, Fig. 3c)
A33: Anaerococcus | B33: bacteria | C33: genus | D33: dry eye disease | E33: unclear | F33: disease_vs_control | G33: other | H33: < 0.01 | I33: medium | J33: verified | K33: keep | L33: Univariate analysis detected the most significant differences in the abundance of MLE112, Lactobacillaceae, Streptococcus, Sphingobium, Caldicoprobacter and Anaerococcus (ANOVA, P < 0.01, Fig. 3c)
A34: Azospirillum | B34: bacteria | C34: genus | D34: dry eye disease | E34: unclear | F34: disease_vs_control | G34: other | H34: < 7.0e-18 | I34: high | J34: verified | K34: keep | L34: negative binomial regression noted the greatest differences in the abundance of the genera Methylobacteriaceae, Pseudomonas, Azospirillum, Bradyrhizobium and Coriobacteriaceae (all with FDR-adjusted P < 7.0 × 10−18)
A35: Coriobacteriaceae | B35: bacteria | C35: family | D35: dry eye disease | E35: unclear | F35: disease_vs_control | G35: other | H35: < 7.0e-18 | I35: high | J35: verified | K35: keep | L35: negative binomial regression noted the greatest differences in the abundance of the genera Methylobacteriaceae, Pseudomonas, Azospirillum, Bradyrhizobium and Coriobacteriaceae (all with FDR-adjusted P < 7.0 × 10−18)
A36: Staphylococcus | B36: bacteria | C36: genus | D36: dry eye disease | E36: unchanged | F36: disease_vs_control | G36: other | I36: high | J36: verified | K36: keep | L36: A more rigorous normalization performed on our dataset confirmed the reduction in Pseudomonas spp. but not in Staphylococcus spp.
A37: OPB58 | B37: bacteria | C37: order | D37: dry eye disease | E37: decreased | F37: disease_vs_control | G37: other | I37: medium | J37: verified | K37: keep_flagged | L37: discriminant analysis of principal components at the order level identified OPB58 and Bacteroidetes as important discriminators of the normal eye. In individuals with dry eye, additional orders enabled further discrimination, with Flavobacteriales, Alteromonadales and Actinomycetes, Anaeroplasmatales and Desulfuromonadales functioning as the primary discriminators
A38: Bacteroidetes | B38: bacteria | C38: phylum | D38: dry eye disease | E38: decreased | F38: disease_vs_control | G38: other | I38: low | J38: verified | K38: keep_flagged | L38: discriminant analysis of principal components at the order level identified OPB58 and Bacteroidetes as important discriminators of the normal eye. In individuals with dry eye, additional orders enabled further discrimination, with Flavobacteriales, Alteromonadales and Actinomycetes, Anaeroplasmatales and Desulfuromonadales functioning as the primary discriminators
A39: Flavobacteriales | B39: bacteria | C39: order | D39: dry eye disease | E39: increased | F39: disease_vs_control | G39: other | I39: medium | J39: verified | K39: keep | L39: discriminant analysis of principal components at the order level identified OPB58 and Bacteroidetes as important discriminators of the normal eye. In individuals with dry eye, additional orders enabled further discrimination, with Flavobacteriales, Alteromonadales and Actinomycetes, Anaeroplasmatales and Desulfuromonadales functioning as the primary discriminators
A40: Alteromonadales | B40: bacteria | C40: order | D40: dry eye disease | E40: increased | F40: disease_vs_control | G40: other | I40: medium | J40: verified | K40: keep | L40: discriminant analysis of principal components at the order level identified OPB58 and Bacteroidetes as important discriminators of the normal eye. In individuals with dry eye, additional orders enabled further discrimination, with Flavobacteriales, Alteromonadales and Actinomycetes, Anaeroplasmatales and Desulfuromonadales functioning as the primary discriminators
...

Sheet P1128
A1: Paper 1128 — Fecal Microbiota Transplantation (FMT) From a Human at Low Risk for Alzheimer's Disease Improves Short-Term Recognition Memory and Increases Neuroinflammation in a 3xTg AD Mouse Model
A2: TAXON NAME | B2: DOMAIN | C2: TAXONOMIC LEVEL | D2: PRIMARY DISEASE | E2: DIRECTION | F2: CHANGE CONTEXT | G2: SAMPLE SITE | H2: P VALUE | I2: CONFIDENCE | J2: AGREEMENT | K2: QUEEN DECISION | L2: VERBATIM EVIDENCE | M2: STATUS | N2: CORRECTION | O2: SAM NOTES
A3: Parabacteroides | B3: bacteria | C3: genus | D3: Alzheimer's disease | E3: increased | F3: treatment_effect | G3: gut | H3: q<0.02 | I3: high | J3: verified | K3: keep | L3: Parabacteroides was increased in the APOEe2-FMT group and both Ligilactobacilus and Coprostanoligenes groups were specifically reduced in the AD-FMT group when compared to the mice-FMT group (Figure 3C).
A4: Prevotellaceae_UGC_001 | B4: bacteria | C4: genus | D4: Alzheimer's disease | E4: increased | F4: treatment_effect | G4: gut | H4: p<0.05 | I4: high | J4: verified | K4: keep | L4: Biophila, Muribaculum, Parabacteroides, and Prevotellaceae_UGC_001 are positively associated, and Desulfovibrio, f_Ruminococcaceae g_uncultured, and g_Anaerotruncus are negatively associated with both neuroinflammation and APOEe2-FMT
A5: Desulfovibrio | B5: bacteria | C5: genus | D5: Alzheimer's disease | E5: decreased | F5: treatment_effect | G5: gut | H5: q<0.02 | I5: high | J5: verified | K5: keep | L5: Rikenella, Eggerthellaceae_uncultured, and Desulfovibrio genera were reduced only in the 'protected' FMT (APOEe2 and young)
A6: Rikenella | B6: bacteria | C6: genus | D6: Alzheimer's disease | E6: decreased | F6: treatment_effect | G6: gut | H6: q<0.02 | I6: high | J6: verified | K6: keep | L6: Rikenella, Eggerthellaceae_uncultured, and Desulfovibrio genera were reduced only in the 'protected' FMT (APOEe2 and young)
A7: Eggerthellaceae_uncultured | B7: bacteria | C7: genus | D7: Alzheimer's disease | E7: decreased | F7: treatment_effect | G7: gut | H7: q<0.02 | I7: high | J7: verified | K7: keep | L7: Rikenella, Eggerthellaceae_uncultured, and Desulfovibrio genera were reduced only in the 'protected' FMT (APOEe2 and young)
A8: Ligilactobacillus | B8: bacteria | C8: genus | D8: Alzheimer's disease | E8: decreased | F8: treatment_effect | G8: gut | H8: q<0.02 | I8: high | J8: verified | K8: keep | L8: both Ligilactobacilus and Coprostanoligenes groups were specifically reduced in the AD-FMT group when compared to the mice-FMT group (Figure 3C)
A9: Coprostanoligenes group | B9: bacteria | C9: genus | D9: Alzheimer's disease | E9: decreased | F9: treatment_effect | G9: gut | H9: q<0.02 | I9: high | J9: verified | K9: keep | L9: both Ligilactobacilus and Coprostanoligenes groups were specifically reduced in the AD-FMT group when compared to the mice-FMT group (Figure 3C)
A10: Phascolactobacterium | B10: bacteria | C10: genus | D10: Alzheimer's disease | E10: increased | F10: treatment_effect | G10: gut | H10: p<0.05 | I10: high | J10: verified | K10: keep | L10: Phascolactobacterium was significantly associated with Young-FMT when compared to both mice and AD-FMT
A11: Biophila | B11: bacteria | C11: genus | D11: Alzheimer's disease | E11: increased | F11: treatment_effect | G11: gut | H11: p<0.05 | I11: low | J11: verified | K11: keep_flagged | L11: Biophila, Muribaculum, Parabacteroides, and Prevotellaceae_UGC_001 are positively associated, and Desulfovibrio, f_Ruminococcaceae g_uncultured, and g_Anaerotruncus are negatively associated with both neuroinflammation and APOEe2-FMT
A12: Muribaculum | B12: bacteria | C12: genus | D12: Alzheimer's disease | E12: increased | F12: treatment_effect | G12: gut | H12: p<0.05 | I12: medium | J12: verified | K12: keep | L12: Biophila, Muribaculum, Parabacteroides, and Prevotellaceae_UGC_001 are positively associated, and Desulfovibrio, f_Ruminococcaceae g_uncultured, and g_Anaerotruncus are negatively associated with both neuroinflammation and APOEe2-FMT
A13: f_Ruminococcaceae g_uncultured | B13: bacteria | C13: genus | D13: Alzheimer's disease | E13: decreased | F13: treatment_effect | G13: gut | H13: p<0.05 | I13: medium | J13: verified | K13: keep | L13: Biophila, Muribaculum, Parabacteroides, and Prevotellaceae_UGC_001 are positively associated, and Desulfovibrio, f_Ruminococcaceae g_uncultured, and g_Anaerotruncus are negatively associated with both neuroinflammation and APOEe2-FMT
A14: Anaerotruncus | B14: bacteria | C14: genus | D14: Alzheimer's disease | E14: decreased | F14: treatment_effect | G14: gut | H14: p<0.05 | I14: medium | J14: verified | K14: keep | L14: Biophila, Muribaculum, Parabacteroides, and Prevotellaceae_UGC_001 are positively associated, and Desulfovibrio, f_Ruminococcaceae g_uncultured, and g_Anaerotruncus are negatively associated with both neuroinflammation and APOEe2-FMT

Sheet P1220
A1: Paper 1220 — Comparative analysis of the bronchoalveolar microbiome in Portuguese patients with different chronic lung disorders
A2: TAXON NAME | B2: DOMAIN | C2: TAXONOMIC LEVEL | D2: PRIMARY DISEASE | E2: DIRECTION | F2: CHANGE CONTEXT | G2: SAMPLE SITE | H2: P VALUE | I2: CONFIDENCE | J2: AGREEMENT | K2: QUEEN DECISION | L2: VERBATIM EVIDENCE | M2: STATUS | N2: CORRECTION | O2: SAM NOTES
A3: Streptococcus | B3: bacteria | C3: genus | D3: lung cancer | E3: increased | F3: disease_vs_control | G3: lung | H3: 0.03852 | I3: high | J3: verified | K3: keep | L3: only Streptococcus diverged between LC and non-LC groups (Wilcoxon rank sum test; p value = 0. 03852; Cohen's dS = 0. 30)
A4: Prevotella | B4: bacteria | C4: genus | D4: lung cancer | E4: increased | F4: disease_vs_control | G4: lung | H4: 0.04405 | I4: high | J4: verified | K4: keep_flagged | L4: Prevotella proportions separated LC* from ILD cases (Wilcoxon rank sum test;p value = 0. 04405; Cohen's dS = 0. 65)
A5: Prevotella | B5: bacteria | C5: genus | D5: interstitial lung disease | E5: decreased | F5: disease_vs_control | G5: lung | H5: 0.04405 | I5: high | J5: verified | K5: keep_flagged | L5: In our study, we observed a decreased prevalence of Prevotella in the ILD cohort, but a higher prevalence in LC*
A6: Haemophilus | B6: bacteria | C6: genus | D6: chronic obstructive pulmonary disease | E6: increased | F6: disease_vs_control | G6: lung | H6: 0.005107 | I6: high | J6: verified | K6: keep | L6: Haemophilus also varied significantly in the ILD versus COPD comparison (Wilcoxon rank sum test; p value = 0. 005107; Cohen's dS = 0. 74)
A7: Haemophilus | B7: bacteria | C7: genus | D7: interstitial lung disease | E7: decreased | F7: disease_vs_control | G7: lung | H7: 0.005107 | I7: high | J7: verified | K7: keep_flagged | L7: Haemophilus was enhanced in COPD versus ILD
A8: Pseudomonas | B8: bacteria | C8: genus | D8: interstitial lung disease | E8: increased | F8: disease_vs_control | G8: lung | I8: low | J8: verified | K8: keep_flagged | L8: The genera Pseudomonas and Staphylococcus previously described as associated with a worse IPF prognosis tended to be higher in our ILD cases compared to COPD and LC*, but this was not significant
A9: Staphylococcus | B9: bacteria | C9: genus | D9: interstitial lung disease | E9: increased | F9: disease_vs_control | G9: lung | I9: low | J9: verified | K9: keep_flagged | L9: The genera Pseudomonas and Staphylococcus previously described as associated with a worse IPF prognosis tended to be higher in our ILD cases compared to COPD and LC*, but this was not significant

Sheet P1240
A1: Paper 1240 — Whole Genome Profiling of Lung Microbiome in Solid Organ Transplant Recipients Reveals Virus Involved Microecology May Worsen Prognosis
A2: TAXON NAME | B2: DOMAIN | C2: TAXONOMIC LEVEL | D2: PRIMARY DISEASE | E2: DIRECTION | F2: CHANGE CONTEXT | G2: SAMPLE SITE | H2: P VALUE | I2: CONFIDENCE | J2: AGREEMENT | K2: QUEEN DECISION | L2: VERBATIM EVIDENCE | M2: STATUS | N2: CORRECTION | O2: SAM NOTES
A3: Pneumocystis jirovecii | B3: fungi | C3: species | D3: respiratory infection in solid organ transplant recipients | E3: increased | F3: disease_vs_control | G3: lung | I3: medium | J3: verified | K3: keep | L3: A further comparison of species of microorganisms in the virus-positive group and the virus-negative group showed significant differences in the top 20 lung species (such as Pneumocystis jirovecii, Moraxella osloensis, CMV) and other species beyond the top 20
A4: Pneumocystis jirovecii | B4: fungi | C4: species | D4: respiratory infection in solid organ transplant recipients | E4: increased | F4: disease_vs_control | G4: lung | I4: medium | J4: verified | K4: keep | L4: Microbial analysis showed significant differences in top-20 species (such as Pneumocystis jirovecii and Veillonella parvula) and other species... Our results showed that compared with the corresponding negative group, PJP was significantly different in the virus-positive and CMV-positive groups... 71.4% (10/14) of CMV-positive cases were associated with PJP infection
A5: Moraxella osloensis | B5: bacteria | C5: species | D5: respiratory infection in solid organ transplant recipients | E5: decreased | F5: disease_vs_control | G5: lung | I5: medium | J5: verified | K5: keep | L5: the proportion of Moraxella osloensis, one of the top 20 species in lung microbiology, decreased in the virus-positive group
A6: Veillonella parvula | B6: bacteria | C6: species | D6: respiratory infection in solid organ transplant recipients | E6: decreased | F6: disease_vs_control | G6: lung | I6: medium | J6: verified | K6: keep | L6: the proportion of Veillonella parvula, also one of the top 20 species in lung microbiology, decreased in the CMV-positive group

Sheet P134
A1: Paper 134 — Shotgun metagenomics reveals the gut microbial diversity and functions in Vespa mandarinia (Hymenoptera: Vespidae) at multiple life stages
A2: TAXON NAME | B2: DOMAIN | C2: TAXONOMIC LEVEL | D2: PRIMARY DISEASE | E2: DIRECTION | F2: CHANGE CONTEXT | G2: SAMPLE SITE | H2: P VALUE | I2: CONFIDENCE | J2: AGREEMENT | K2: QUEEN DECISION | L2: VERBATIM EVIDENCE | M2: STATUS | N2: CORRECTION | O2: SAM NOTES
A3: No relationships extracted — please review paper manually and add below if needed.

Sheet P141
A1: Paper 141 — Reproducibility and Comparability of Fecal Microbiome Associations with Colorectal Cancer in a Cross-Sectional Study
A2: TAXON NAME | B2: DOMAIN | C2: TAXONOMIC LEVEL | D2: PRIMARY DISEASE | E2: DIRECTION | F2: CHANGE CONTEXT | G2: SAMPLE SITE | H2: P VALUE | I2: CONFIDENCE | J2: AGREEMENT | K2: QUEEN DECISION | L2: VERBATIM EVIDENCE | M2: STATUS | N2: CORRECTION | O2: SAM NOTES
A3: Fusobacteria | B3: bacteria | C3: phylum | D3: colorectal cancer | E3: increased | F3: disease_vs_control | G3: fecal | H3: 0.003 | I3: high | J3: unanimous | K3: keep | L3: we reproduced a significant association between the presence of the Fusobacteria phyla and CRC case status (p = 0. 003), specifically that 76. 9% of cases and 48. 1% of controls had detectable Fusobacteria.
A4: Fusobacterium | B4: bacteria | C4: genus | D4: colorectal cancer | E4: increased | F4: disease_vs_control | G4: fecal | H4: 0.006 | I4: high | J4: unanimous | K4: keep | L4: the WGSS also had higher prevalent detection rate for other taxa, and it reproduced a significant association between the presence of Fusobacterium (p = 0. 006)
A5: Porphyromonas | B5: bacteria | C5: genus | D5: colorectal cancer | E5: increased | F5: disease_vs_control | G5: fecal | H5: 0.032 | I5: high | J5: unanimous | K5: keep | L5: reproduced a significant association between the presence of Fusobacterium (p = 0. 006) and Porphyromonas (p = 0. 032) with CRC case status.
A6: Atopobium | B6: bacteria | C6: genus | D6: colorectal cancer | E6: unchanged | F6: disease_vs_control | G6: fecal | H6: 0.328 | I6: high | J6: majority | K6: keep | L6: The association between Atopobium and CRC from the 16S DC was not reproduced in the WGSS (Table 2)
A7: Clostridia | B7: bacteria | C7: class | D7: colorectal cancer | E7: decreased | F7: disease_vs_control | G7: fecal | H7: 0.092 | I7: medium | J7: majority | K7: keep_flagged | L7: we did not reproduce associations between the relative abundance of specific taxa and CRC case status, although the association between the relative abundance of Clostridia tended to be lower in cases (p = 0. 092).
A8: Coprococcus | B8: bacteria | C8: genus | D8: colorectal cancer | E8: unchanged | F8: disease_vs_control | G8: fecal | H8: 0.977 | I8: high | J8: majority | K8: keep | L8: Coprococcus 1.2% cases vs 1.4% controls, p=0.977 (Table 3, WGSS DC)
A9: Bacteroidia | B9: bacteria | C9: class | D9: colorectal cancer | E9: unchanged | F9: disease_vs_control | G9: fecal | I9: low | J9: single_extractor | K9: keep_flagged | L9: the class with a highest relative abundance was Bacteroidia, which had a relative abundance of 53. 2% in cases and 50. 9% in controls (S1 Table).
A10: Fusobacteria | B10: bacteria | C10: phylum | D10: colorectal cancer | E10: increased | F10: disease_vs_control | G10: fecal | H10: 0.007 | I10: high | J10: late_discovery | K10: keep | L10: Fusobacteria (phylum) 36.2% cases vs 16.0% controls, p=0.007 (Table 2, 16S DC)
A11: Fusobacterium | B11: bacteria | C11: genus | D11: colorectal cancer | E11: increased | F11: disease_vs_control | G11: fecal | H11: 0.004 | I11: high | J11: late_discovery | K11: keep | L11: Fusobacterium 31.9% cases vs 11.7% controls, p=0.004 (Table 2, 16S DC)
A12: Atopobium | B12: bacteria | C12: genus | D12: colorectal cancer | E12: increased | F12: disease_vs_control | G12: fecal | H12: <0.001 | I12: high | J12: late_discovery | K12: keep | L12: Atopobium 19.2% cases vs 2.1% controls, p<0.001 (Table 2, 16S DC)
A13: Porphyromonas | B13: bacteria | C13: genus | D13: colorectal cancer | E13: increased | F13: disease_vs_control | G13: fecal | H13: 0.001 | I13: high | J13: late_discovery | K13: keep | L13: Porphyromonas 27.7% cases vs 7.5% controls, p=0.001 (Table 2, 16S DC)
A14: Clostridia | B14: bacteria | C14: class | D14: colorectal cancer | E14: decreased | F14: disease_vs_control | G14: fecal | H14: 0.005 | I14: high | J14: late_discovery | K14: keep | L14: Clostridia (class) 68.6% cases vs 77.8% controls, p=0.005 (Table 3, 16S DC)
A15: Coprococcus | B15: bacteria | C15: genus | D15: colorectal cancer | E15: decreased | F15: disease_vs_control | G15: fecal | H15: 0.002 | I15: high | J15: late_discovery | K15: keep | L15: Coprococcus 1.7% cases vs 3.7% controls, p=0.002 (Table 3, 16S DC)

Sheet P1421
A1: Paper 1421 — Periodontitis-related salivary microbiota aggravates Alzheimer's disease via gut-brain axis crosstalk
A2: TAXON NAME | B2: DOMAIN | C2: TAXONOMIC LEVEL | D2: PRIMARY DISEASE | E2: DIRECTION | F2: CHANGE CONTEXT | G2: SAMPLE SITE | H2: P VALUE | I2: CONFIDENCE | J2: AGREEMENT | K2: QUEEN DECISION | L2: VERBATIM EVIDENCE | M2: STATUS | N2: CORRECTION | O2: SAM NOTES
A3: Bacteroidetes | B3: bacteria | C3: phylum | D3: Alzheimer's disease | E3: increased | F3: disease_vs_control | G3: oral | I3: medium | J3: verified | K3: keep_flagged | L3: The phylum Bacteroidetes showed a tendency to increase in abundance, and Firmicutes decreased in the PS group compared to the HS group.
A4: Firmicutes | B4: bacteria | C4: phylum | D4: Alzheimer's disease | E4: decreased | F4: disease_vs_control | G4: oral | I4: medium | J4: verified | K4: keep | L4: The phylum Bacteroidetes showed a tendency to increase in abundance, and Firmicutes decreased in the PS group compared to the HS group.
A5: Treponema | B5: bacteria | C5: genus | D5: Alzheimer's disease | E5: increased | F5: disease_vs_control | G5: oral | H5: < 0.05 | I5: high | J5: verified | K5: keep | L5: Periodontal pathogens such as Treponema, Porphyromonas, and Fusobacterium, were enriched in periodontitis saliva according to the random forest and linear discriminant analysis effect size (LEfSe) results.
A6: Porphyromonas | B6: bacteria | C6: genus | D6: Alzheimer's disease | E6: increased | F6: disease_vs_control | G6: oral | H6: < 0.05 | I6: high | J6: verified | K6: keep | L6: Periodontal pathogens such as Treponema, Porphyromonas, and Fusobacterium, were enriched in periodontitis saliva according to the random forest and linear discriminant analysis effect size (LEfSe) results.
A7: Fusobacterium | B7: bacteria | C7: genus | D7: Alzheimer's disease | E7: increased | F7: disease_vs_control | G7: oral | H7: < 0.05 | I7: high | J7: verified | K7: keep | L7: Periodontal pathogens such as Treponema, Porphyromonas, and Fusobacterium, were enriched in periodontitis saliva according to the random forest and linear discriminant analysis effect size (LEfSe) results.
A8: Bacteroidetes | B8: bacteria | C8: phylum | D8: Alzheimer's disease | E8: increased | F8: treatment_effect | G8: fecal | H8: < 0.05 | I8: high | J8: verified | K8: keep | L8: At the phylum level, the amount of Bacteroidetes increased by 28.33%, while that of Firmicutes decreased by 27.66% in the P group versus the H group.
A9: Firmicutes | B9: bacteria | C9: phylum | D9: Alzheimer's disease | E9: decreased | F9: treatment_effect | G9: fecal | H9: < 0.05 | I9: high | J9: verified | K9: keep | L9: At the phylum level, the amount of Bacteroidetes increased by 28.33%, while that of Firmicutes decreased by 27.66% in the P group versus the H group.
A10: Sutterella | B10: bacteria | C10: genus | D10: Alzheimer's disease | E10: increased | F10: treatment_effect | G10: fecal | H10: < 0.01 | I10: high | J10: verified | K10: keep | L10: the relative abundance of Sutterella was significantly increased in the P group versus the H group (p < .01) (Figure S1A)
A11: Lactobacillus | B11: bacteria | C11: genus | D11: Alzheimer's disease | E11: decreased | F11: treatment_effect | G11: fecal | I11: low | J11: verified | K11: keep_flagged | L11: that of Lactobacillus was reduced in the P group, although no significant difference between groups was found (Figure S1B)
A12: Odoribacter | B12: bacteria | C12: genus | D12: Alzheimer's disease | E12: unclear | F12: treatment_effect | G12: fecal | I12: low | J12: verified | K12: keep_flagged | L12: Odoribacter, Sutterella, Ruminococcus, Helicobacter, Allobaculum, Oscillospira, Rikenella, and Dorea were the most representative differential microbiota between the P and H groups, according to the LEfSe results and random forest analysis... Sutterella, Allobaculum, and Odoribacter displayed strong positive correlations with the AD-related parameters.
A13: Allobaculum | B13: bacteria | C13: genus | D13: Alzheimer's disease | E13: unclear | F13: treatment_effect | G13: fecal | I13: low | J13: verified | K13: keep_flagged | L13: Odoribacter, Sutterella, Ruminococcus, Helicobacter, Allobaculum, Oscillospira, Rikenella, and Dorea were the most representative differential microbiota between the P and H groups, according to the LEfSe results and random forest analysis... Sutterella, Allobaculum, and Odoribacter displayed strong positive correlations with the AD-related parameters.
A14: Ruminococcus | B14: bacteria | C14: genus | D14: Alzheimer's disease | E14: unclear | F14: treatment_effect | G14: fecal | I14: low | J14: verified | K14: keep_flagged | L14: Odoribacter, Sutterella, Ruminococcus, Helicobacter, Allobaculum, Oscillospira, Rikenella, and Dorea were the most representative differential microbiota between the P and H groups... Lactobacillus, Oscillospira, Ruminococcus, Rikenella, and Helicobacter were negatively correlated with most AD phenotypes.
A15: Helicobacter | B15: bacteria | C15: genus | D15: Alzheimer's disease | E15: unclear | F15: treatment_effect | G15: fecal | I15: low | J15: verified | K15: keep_flagged | L15: Odoribacter, Sutterella, Ruminococcus, Helicobacter, Allobaculum, Oscillospira, Rikenella, and Dorea were the most representative differential microbiota between the P and H groups... Lactobacillus, Oscillospira, Ruminococcus, Rikenella, and Helicobacter were negatively correlated with most AD phenotypes.
A16: Oscillospira | B16: bacteria | C16: genus | D16: Alzheimer's disease | E16: unclear | F16: treatment_effect | G16: fecal | I16: low | J16: verified | K16: keep_flagged | L16: Odoribacter, Sutterella, Ruminococcus, Helicobacter, Allobaculum, Oscillospira, Rikenella, and Dorea were the most representative differential microbiota between the P and H groups... Lactobacillus, Oscillospira, Ruminococcus, Rikenella, and Helicobacter were negatively correlated with most AD phenotypes.
A17: Rikenella | B17: bacteria | C17: genus | D17: Alzheimer's disease | E17: unclear | F17: treatment_effect | G17: fecal | I17: low | J17: verified | K17: keep_flagged | L17: Odoribacter, Sutterella, Ruminococcus, Helicobacter, Allobaculum, Oscillospira, Rikenella, and Dorea were the most representative differential microbiota between the P and H groups... Lactobacillus, Oscillospira, Ruminococcus, Rikenella, and Helicobacter were negatively correlated with most AD phenotypes.

Sheet P1594
A1: Paper 1594 — The altered sputum microbiome profile in patients with moderate and severe COPD exacerbations, compared to the healthy group in the Indian population
A2: TAXON NAME | B2: DOMAIN | C2: TAXONOMIC LEVEL | D2: PRIMARY DISEASE | E2: DIRECTION | F2: CHANGE CONTEXT | G2: SAMPLE SITE | H2: P VALUE | I2: CONFIDENCE | J2: AGREEMENT | K2: QUEEN DECISION | L2: VERBATIM EVIDENCE | M2: STATUS | N2: CORRECTION | O2: SAM NOTES
A3: Firmicutes | B3: bacteria | C3: phylum | D3: chronic obstructive pulmonary disease (COPD) | E3: increased | F3: disease_vs_control | G3: respiratory | I3: high | J3: verified | K3: keep | L3: A significantly higher proportion of Firmicutes and Actinobacteria were present in respiratory samples from patients with moderate COPD and Proteobacteria was comparatively increased in severe COPD, whereas in healthy individuals, Bacteroidetes and Fusobacteria were present in a higher abundance compared to both COPD groups.
